Workbook

Sheet README
A1: Project Broadcast — Issue 6: Ukraine Manpower Runway vs UGV Integration (v2, Sep 2026)
A3: What this model does
A4: Estimates how long Ukraine can keep enough men in uniform to hold the line if fighting continues, then measures how much runway unmanned ground vehicles (UGVs) add.
A5: v2 supersedes the Aug 2026 figures (1.9 / 3.5 / 5.8 yrs). The Dashboard bridge walks from the old Central number to the new one step by step.
A7: Structure (stock-flow)
A8: • Pool = men already serving (S) + reachable reserve not yet in uniform (R). Built bottom-up and includes all future intake.
A9: • Each month: intake moves men R → S (capped by mobilization capacity). S loses irrecoverable losses, net permanent AWOL and discharges.
A10: • Collapse = S falls below the minimum force to hold the line (front km × line troops/km × (1 + support ratio)). That can happen with reserve left (throughput-bound) or once the pool is exhausted.
A12: UGV channels
A13: • Ch1 loss-rate: robots take logistics/casevac and some combat missions ABOVE today's level (today's use is already in the loss rate). Coverage is capped by UGV supply × survivability, and operators are added to the minimum force.
A14: • Ch2 headcount: robots replace a share of line troops (net of operators), cutting both exposure and the line requirement.
A15: • Combined applies both with an overlap haircut. UGVs cannot reduce AWOL or discharges (~40% of Central net drain).
... A33: Blue text = hardcoded input · Black = formula · Green = link to another sheet · Yellow fill = key judgment, no hard data.

Sheet Dashboard
A1: Dashboard — Ukraine manpower runway & UGV effect (v2, supersedes Aug 2026 figures)
A2: ="Years from "&TEXT(Inputs!B67,"mmm yyyy")&" until the serving force falls below the minimum force needed to hold the line. '>20' = survives the 240-month horizon. Active UGV set: "&Inputs!B40 -> Years from Sep 2026 until the serving force falls below the minimum force needed to hold the line. '>20' = survives the 240-month horizon. Active UGV set: Central
G3: Chart data — Central scenario, serving force vs minimum force (men)
A4: Years to collapse | B4: Base (UGVs frozen at today) | C4: Ch1: loss-rate | D4: Ch2: headcount | E4: Combined | G4: Year | H4: Serving (Base) | I4: Serving (Combined) | J4: Min force (Base) | K4: Min force (Combined)
A5: Pessimistic | B5: {=IFERROR(_xlfn.LET(_xlpm.i,MATCH(1,Engine!$U$5:$U$245,0),IF(_xlpm.i=1,0,((_xlpm.i-2)+INDEX(Engine!$T$5:$T$245,_xlpm.i-1)/(INDEX(Engine!$T$5:$T$245,_xlpm.i-1)-INDEX(Engine!$T$5:$T$245,_xlpm.i)))/12)),">20")} -> 1.1305808 | C5: {=IFERROR(_xlfn.LET(_xlpm.i,MATCH(1,Engine!$AV$5:$AV$245,0),IF(_xlpm.i=1,0,((_xlpm.i-2)+INDEX(Engine!$AU$5:$AU$245,_xlpm.i-1)/(INDEX(Engine!$AU$5:$AU$245,_xlpm.i-1)-INDEX(Engine!$AU$5:$AU$245,_xlpm.i)))/12)),">20")} -> 1.2112005 | D5: {=IFERROR(_xlfn.LET(_xlpm.i,MATCH(1,Engine!$BW$5:$BW$245,0),IF(_xlpm.i=1,0,((_xlpm.i-2)+INDEX(Engine!$BV$5:$BV$245,_xlpm.i-1)/(INDEX(Engine!$BV$5:$BV$245,_xlpm.i-1)-INDEX(Engine!$BV$5:$BV$245,_xlpm.i)))/12)),">20")} -> 1.2553215 | E5: {=IFERROR(_xlfn.LET(_xlpm.i,MATCH(1,Engine!$CX$5:$CX$245,0),IF(_xlpm.i=1,0,((_xlpm.i-2)+INDEX(Engine!$CW$5:$CW$245,_xlpm.i-1)/(INDEX(Engine!$CW$5:$CW$245,_xlpm.i-1)-INDEX(Engine!$CW$5:$CW$245,_xlpm.i)))/12)),">20")} -> 1.337348 | G5: 0 | H5: {=INDEX(Engine!$Z$5:$Z$245,G5*12+1)} -> 800000 | I5: {=INDEX(Engine!$DC$5:$DC$245,G5*12+1)} -> 800000 | J5: {=INDEX(Engine!$AB$5:$AB$245,G5*12+1)} -> 495000 | K5: {=INDEX(Engine!$DE$5:$DE$245,G5*12+1)} -> 495000
A6: Central | B6: {=IFERROR(_xlfn.LET(_xlpm.i,MATCH(1,Engine!$AD$5:$AD$245,0),IF(_xlpm.i=1,0,((_xlpm.i-2)+INDEX(Engine!$AC$5:$AC$245,_xlpm.i-1)/(INDEX(Engine!$AC$5:$AC$245,_xlpm.i-1)-INDEX(Engine!$AC$5:$AC$245,_xlpm.i)))/12)),">20")} -> 3.5950012 | C6: {=IFERROR(_xlfn.LET(_xlpm.i,MATCH(1,Engine!$BE$5:$BE$245,0),IF(_xlpm.i=1,0,((_xlpm.i-2)+INDEX(Engine!$BD$5:$BD$245,_xlpm.i-1)/(INDEX(Engine!$BD$5:$BD$245,_xlpm.i-1)-INDEX(Engine!$BD$5:$BD$245,_xlpm.i)))/12)),">20")} -> 3.8235914 | D6: {=IFERROR(_xlfn.LET(_xlpm.i,MATCH(1,Engine!$CF$5:$CF$245,0),IF(_xlpm.i=1,0,((_xlpm.i-2)+INDEX(Engine!$CE$5:$CE$245,_xlpm.i-1)/(INDEX(Engine!$CE$5:$CE$245,_xlpm.i-1)-INDEX(Engine!$CE$5:$CE$245,_xlpm.i)))/12)),">20")} -> 3.7735809 | E6: {=IFERROR(_xlfn.LET(_xlpm.i,MATCH(1,Engine!$DG$5:$DG$245,0),IF(_xlpm.i=1,0,((_xlpm.i-2)+INDEX(Engine!$DF$5:$DF$245,_xlpm.i-1)/(INDEX(Engine!$DF$5:$DF$245,_xlpm.i-1)-INDEX(Engine!$DF$5:$DF$245,_xlpm.i)))/12)),">20")} -> 3.9601899 | G6: 1 | H6: {=INDEX(Engine!$Z$5:$Z$245,G6*12+1)} -> 800000 | I6: {=INDEX(Engine!$DC$5:$DC$245,G6*12+1)} -> 800000 | J6: {=INDEX(Engine!$AB$5:$AB$245,G6*12+1)} -> 495000 | K6: {=INDEX(Engine!$DE$5:$DE$245,G6*12+1)} -> 494250
A7: Optimistic | B7: {=IFERROR(_xlfn.LET(_xlpm.i,MATCH(1,Engine!$AM$5:$AM$245,0),IF(_xlpm.i=1,0,((_xlpm.i-2)+INDEX(Engine!$AL$5:$AL$245,_xlpm.i-1)/(INDEX(Engine!$AL$5:$AL$245,_xlpm.i-1)-INDEX(Engine!$AL$5:$AL$245,_xlpm.i)))/12)),">20")} -> 8.9256217 | C7: {=IFERROR(_xlfn.LET(_xlpm.i,MATCH(1,Engine!$BN$5:$BN$245,0),IF(_xlpm.i=1,0,((_xlpm.i-2)+INDEX(Engine!$BM$5:$BM$245,_xlpm.i-1)/(INDEX(Engine!$BM$5:$BM$245,_xlpm.i-1)-INDEX(Engine!$BM$5:$BM$245,_xlpm.i)))/12)),">20")} -> 9.7599385 | D7: {=IFERROR(_xlfn.LET(_xlpm.i,MATCH(1,Engine!$CO$5:$CO$245,0),IF(_xlpm.i=1,0,((_xlpm.i-2)+INDEX(Engine!$CN$5:$CN$245,_xlpm.i-1)/(INDEX(Engine!$CN$5:$CN$245,_xlpm.i-1)-INDEX(Engine!$CN$5:$CN$245,_xlpm.i)))/12)),">20")} -> 9.557684 | E7: {=IFERROR(_xlfn.LET(_xlpm.i,MATCH(1,Engine!$DP$5:$DP$245,0),IF(_xlpm.i=1,0,((_xlpm.i-2)+INDEX(Engine!$DO$5:$DO$245,_xlpm.i-1)/(INDEX(Engine!$DO$5:$DO$245,_xlpm.i-1)-INDEX(Engine!$DO$5:$DO$245,_xlpm.i)))/12)),">20")} -> 10.159425 | G7: 2 | H7: {=INDEX(Engine!$Z$5:$Z$245,G7*12+1)} -> 800000 | I7: {=INDEX(Engine!$DC$5:$DC$245,G7*12+1)} -> 800000 | J7: {=INDEX(Engine!$AB$5:$AB$245,G7*12+1)} -> 495000 | K7: {=INDEX(Engine!$DE$5:$DE$245,G7*12+1)} -> 493500
G8: 3 | H8: {=INDEX(Engine!$Z$5:$Z$245,G8*12+1)} -> 628001.37 | I8: {=INDEX(Engine!$DC$5:$DC$245,G8*12+1)} -> 676755.81 | J8: {=INDEX(Engine!$AB$5:$AB$245,G8*12+1)} -> 495000 | K8: {=INDEX(Engine!$DE$5:$DE$245,G8*12+1)} -> 489750
A9: Runway added vs Base (yrs) | B9: Base (UGVs frozen at today) | C9: Ch1: loss-rate | D9: Ch2: headcount | E9: Combined | G9: 4 | H9: {=INDEX(Engine!$Z$5:$Z$245,G9*12+1)} -> 411822.69 | I9: {=INDEX(Engine!$DC$5:$DC$245,G9*12+1)} -> 478838.83 | J9: {=INDEX(Engine!$AB$5:$AB$245,G9*12+1)} -> 495000 | K9: {=INDEX(Engine!$DE$5:$DE$245,G9*12+1)} -> 486000
A10: Pessimistic | B10: =IFERROR(B5-$B5,"n/a") -> 0 | C10: =IFERROR(C5-$B5,"n/a") -> 0.08061965 | D10: =IFERROR(D5-$B5,"n/a") -> 0.12474068 | E10: =IFERROR(E5-$B5,"n/a") -> 0.20676712 | G10: 5 | H10: {=INDEX(Engine!$Z$5:$Z$245,G10*12+1)} -> 231621.05 | I10: {=INDEX(Engine!$DC$5:$DC$245,G10*12+1)} -> 310623.31 | J10: {=INDEX(Engine!$AB$5:$AB$245,G10*12+1)} -> 495000 | K10: {=INDEX(Engine!$DE$5:$DE$245,G10*12+1)} -> 486000
A11: Central | B11: =IFERROR(B6-$B6,"n/a") -> 0 | C11: =IFERROR(C6-$B6,"n/a") -> 0.22859019 | D11: =IFERROR(D6-$B6,"n/a") -> 0.17857976 | E11: =IFERROR(E6-$B6,"n/a") -> 0.36518871 | G11: 6 | H11: {=INDEX(Engine!$Z$5:$Z$245,G11*12+1)} -> 88072.244 | I11: {=INDEX(Engine!$DC$5:$DC$245,G11*12+1)} -> 170284.97 | J11: {=INDEX(Engine!$AB$5:$AB$245,G11*12+1)} -> 495000 | K11: {=INDEX(Engine!$DE$5:$DE$245,G11*12+1)} -> 486000
A12: Optimistic | B12: =IFERROR(B7-$B7,"n/a") -> 0 | C12: =IFERROR(C7-$B7,"n/a") -> 0.83431685 | D12: =IFERROR(D7-$B7,"n/a") -> 0.63206236 | E12: =IFERROR(E7-$B7,"n/a") -> 1.2338036 | G12: 7 | H12: {=INDEX(Engine!$Z$5:$Z$245,G12*12+1)} -> 0 | I12: {=INDEX(Engine!$DC$5:$DC$245,G12*12+1)} -> 58669.764 | J12: {=INDEX(Engine!$AB$5:$AB$245,G12*12+1)} -> 495000 | K12: {=INDEX(Engine!$DE$5:$DE$245,G12*12+1)} -> 486000
G13: 8 | H13: {=INDEX(Engine!$Z$5:$Z$245,G13*12+1)} -> 0 | I13: {=INDEX(Engine!$DC$5:$DC$245,G13*12+1)} -> 0 | J13: {=INDEX(Engine!$AB$5:$AB$245,G13*12+1)} -> 495000 | K13: {=INDEX(Engine!$DE$5:$DE$245,G13*12+1)} -> 486000
A14: Runway added vs Base (%) | B14: Base (UGVs frozen at today) | C14: Ch1: loss-rate | D14: Ch2: headcount | E14: Combined | G14: 9 | H14: {=INDEX(Engine!$Z$5:$Z$245,G14*12+1)} -> 0 | I14: {=INDEX(Engine!$DC$5:$DC$245,G14*12+1)} -> 0 | J14: {=INDEX(Engine!$AB$5:$AB$245,G14*12+1)} -> 495000 | K14: {=INDEX(Engine!$DE$5:$DE$245,G14*12+1)} -> 486000
A15: Pessimistic | B15: =IFERROR(B5/$B5-1,"n/a") -> 0 | C15: =IFERROR(C5/$B5-1,"n/a") -> 0.071308169 | D15: =IFERROR(D5/$B5-1,"n/a") -> 0.11033327 | E15: =IFERROR(E5/$B5-1,"n/a") -> 0.18288574 | G15: 10 | H15: {=INDEX(Engine!$Z$5:$Z$245,G15*12+1)} -> 0 | I15: {=INDEX(Engine!$DC$5:$DC$245,G15*12+1)} -> 0 | J15: {=INDEX(Engine!$AB$5:$AB$245,G15*12+1)} -> 495000 | K15: {=INDEX(Engine!$DE$5:$DE$245,G15*12+1)} -> 486000
A16: Central | B16: =IFERROR(B6/$B6-1,"n/a") -> 0 | C16: =IFERROR(C6/$B6-1,"n/a") -> 0.063585568 | D16: =IFERROR(D6/$B6-1,"n/a") -> 0.049674464 | E16: =IFERROR(E6/$B6-1,"n/a") -> 0.10158236 | G16: 11 | H16: {=INDEX(Engine!$Z$5:$Z$245,G16*12+1)} -> 0 | I16: {=INDEX(Engine!$DC$5:$DC$245,G16*12+1)} -> 0 | J16: {=INDEX(Engine!$AB$5:$AB$245,G16*12+1)} -> 495000 | K16: {=INDEX(Engine!$DE$5:$DE$245,G16*12+1)} -> 486000
A17: Optimistic | B17: =IFERROR(B7/$B7-1,"n/a") -> 0 | C17: =IFERROR(C7/$B7-1,"n/a") -> 0.093474369 | D17: =IFERROR(D7/$B7-1,"n/a") -> 0.07081438 | E17: =IFERROR(E7/$B7-1,"n/a") -> 0.13823167 | G17: 12 | H17: {=INDEX(Engine!$Z$5:$Z$245,G17*12+1)} -> 0 | I17: {=INDEX(Engine!$DC$5:$DC$245,G17*12+1)} -> 0 | J17: {=INDEX(Engine!$AB$5:$AB$245,G17*12+1)} -> 495000 | K17: {=INDEX(Engine!$DE$5:$DE$245,G17*12+1)} -> 486000
A19: Implied collapse month | B19: Base (UGVs frozen at today) | C19: Ch1: loss-rate | D19: Ch2: headcount | E19: Combined
A20: Pessimistic | B20: =IF(ISNUMBER(B5),EDATE(Inputs!$B$67,ROUNDDOWN(B5*12,0)),"after "&TEXT(EDATE(Inputs!$B$67,240),"yyyy")) -> 46661 | C20: =IF(ISNUMBER(C5),EDATE(Inputs!$B$67,ROUNDDOWN(C5*12,0)),"after "&TEXT(EDATE(Inputs!$B$67,240),"yyyy")) -> 46692 | D20: =IF(ISNUMBER(D5),EDATE(Inputs!$B$67,ROUNDDOWN(D5*12,0)),"after "&TEXT(EDATE(Inputs!$B$67,240),"yyyy")) -> 46722 | E20: =IF(ISNUMBER(E5),EDATE(Inputs!$B$67,ROUNDDOWN(E5*12,0)),"after "&TEXT(EDATE(Inputs!$B$67,240),"yyyy")) -> 46753
A21: Central | B21: =IF(ISNUMBER(B6),EDATE(Inputs!$B$67,ROUNDDOWN(B6*12,0)),"after "&TEXT(EDATE(Inputs!$B$67,240),"yyyy")) -> 47574 | C21: =IF(ISNUMBER(C6),EDATE(Inputs!$B$67,ROUNDDOWN(C6*12,0)),"after "&TEXT(EDATE(Inputs!$B$67,240),"yyyy")) -> 47635 | D21: =IF(ISNUMBER(D6),EDATE(Inputs!$B$67,ROUNDDOWN(D6*12,0)),"after "&TEXT(EDATE(Inputs!$B$67,240),"yyyy")) -> 47635 | E21: =IF(ISNUMBER(E6),EDATE(Inputs!$B$67,ROUNDDOWN(E6*12,0)),"after "&TEXT(EDATE(Inputs!$B$67,240),"yyyy")) -> 47696
A22: Optimistic | B22: =IF(ISNUMBER(B7),EDATE(Inputs!$B$67,ROUNDDOWN(B7*12,0)),"after "&TEXT(EDATE(Inputs!$B$67,240),"yyyy")) -> 49522 | C22: =IF(ISNUMBER(C7),EDATE(Inputs!$B$67,ROUNDDOWN(C7*12,0)),"after "&TEXT(EDATE(Inputs!$B$67,240),"yyyy")) -> 49827 | D22: =IF(ISNUMBER(D7),EDATE(Inputs!$B$67,ROUNDDOWN(D7*12,0)),"after "&TEXT(EDATE(Inputs!$B$67,240),"yyyy")) -> 49735 | E22: =IF(ISNUMBER(E7),EDATE(Inputs!$B$67,ROUNDDOWN(E7*12,0)),"after "&TEXT(EDATE(Inputs!$B$67,240),"yyyy")) -> 49949
A24: Binding constraint at collapse | B24: Base (UGVs frozen at today) | C24: Ch1: loss-rate | D24: Ch2: headcount | E24: Combined
A25: Pessimistic | B25: =IFERROR(IF(INDEX(Engine!$R$5:$R$245,MATCH(1,Engine!$U$5:$U$245,0))>1,"Throughput","Pool exhausted"),"Survives 20 yrs") -> Throughput | C25: =IFERROR(IF(INDEX(Engine!$AS$5:$AS$245,MATCH(1,Engine!$AV$5:$AV$245,0))>1,"Throughput","Pool exhausted"),"Survives 20 yrs") -> Throughput | D25: =IFERROR(IF(INDEX(Engine!$BT$5:$BT$245,MATCH(1,Engine!$BW$5:$BW$245,0))>1,"Throughput","Pool exhausted"),"Survives 20 yrs") -> Throughput | E25: =IFERROR(IF(INDEX(Engine!$CU$5:$CU$245,MATCH(1,Engine!$CX$5:$CX$245,0))>1,"Throughput","Pool exhausted"),"Survives 20 yrs") -> Pool exhausted
A26: Central | B26: =IFERROR(IF(INDEX(Engine!$AA$5:$AA$245,MATCH(1,Engine!$AD$5:$AD$245,0))>1,"Throughput","Pool exhausted"),"Survives 20 yrs") -> Pool exhausted | C26: =IFERROR(IF(INDEX(Engine!$BB$5:$BB$245,MATCH(1,Engine!$BE$5:$BE$245,0))>1,"Throughput","Pool exhausted"),"Survives 20 yrs") -> Pool exhausted | D26: =IFERROR(IF(INDEX(Engine!$CC$5:$CC$245,MATCH(1,Engine!$CF$5:$CF$245,0))>1,"Throughput","Pool exhausted"),"Survives 20 yrs") -> Pool exhausted | E26: =IFERROR(IF(INDEX(Engine!$DD$5:$DD$245,MATCH(1,Engine!$DG$5:$DG$245,0))>1,"Throughput","Pool exhausted"),"Survives 20 yrs") -> Pool exhausted
A27: Optimistic | B27: =IFERROR(IF(INDEX(Engine!$AJ$5:$AJ$245,MATCH(1,Engine!$AM$5:$AM$245,0))>1,"Throughput","Pool exhausted"),"Survives 20 yrs") -> Pool exhausted | C27: =IFERROR(IF(INDEX(Engine!$BK$5:$BK$245,MATCH(1,Engine!$BN$5:$BN$245,0))>1,"Throughput","Pool exhausted"),"Survives 20 yrs") -> Pool exhausted | D27: =IFERROR(IF(INDEX(Engine!$CL$5:$CL$245,MATCH(1,Engine!$CO$5:$CO$245,0))>1,"Throughput","Pool exhausted"),"Survives 20 yrs") -> Pool exhausted | E27: =IFERROR(IF(INDEX(Engine!$DM$5:$DM$245,MATCH(1,Engine!$DP$5:$DP$245,0))>1,"Throughput","Pool exhausted"),"Survives 20 yrs") -> Pool exhausted
A29: Central scenario — key numbers | B29: Value | C29: What it means
A30: Total spendable pool (serving + reachable reserve) | B30: =Inputs!C13 -> 1394000 | C30: Lifetime stock of men who could fight
A31: Minimum force to hold the line | B31: =Inputs!C22 -> 495000 | C31: Collapse threshold (front km × men/km × support ratio)
A32: Spendable margin | B32: =Inputs!C23 -> 899000 | C32: Men that can be lost before the line fails
A33: Net monthly drain at start | B33: =Inputs!C34 -> 21250 | C33: Irrecoverable losses + net AWOL + discharges
A34: Gross monthly outflow | B34: =Inputs!C35 -> 29500 | C34: Cross-check: Budanov says ≥30k/mo intake needed to stand still
A35: Mobilization capacity / month | B35: =Inputs!C36 -> 30000 | C35: If below net drain, the binding constraint is throughput, not the pool
A36: Logistics UGV coverage reached at month 24 | B36: =Engine!E29 -> 0.7 | C36: After supply cap (active UGV set)
A37: Ch1 loss-rate cut vs today at month 36 | B37: =1-Engine!G41 -> 0.15768725 | C37: Share of irrecoverable losses avoided
A38: Months where UGV supply caps coverage | B38: =SUM(Engine!K5:K245) -> 0 | C38: Production × survivability can't keep up with target
A39: Extra UGV crews needed at month 36 | B39: =Engine!J41 -> 6000 | C39: Added to minimum force in Ch1 cases
A41: Bridge: Aug 2026 published → v2 Base (Central) | B41: Years | C41: Change
A42: Start: Aug 2026 published (750k pool, 30% floor, 12.5k/mo) | B42: =Inputs!C14*(1-Inputs!C24)/Inputs!C27/12 -> 3.5
A43: Step 1: bottom-up pool (serving + reachable reserve), same 30% floor | B43: =Inputs!C13*(1-Inputs!C24)/Inputs!C27/12 -> 6.5053333 | C43: =IFERROR(B43-B42,"n/a") -> 3.0053333
A44: Step 2: absolute minimum force replaces % floor | B44: =(Inputs!C13-Inputs!C22)/Inputs!C27/12 -> 5.9933333 | C44: =IFERROR(B44-B43,"n/a") -> -0.512
...

Sheet Article Table
A1: Article Table — Section 3 (v2; supersedes Aug 2026 figures)
A2: ="Years from "&TEXT(Inputs!B67,"mmm yyyy")&" until the serving force falls below the minimum needed to hold the line. Active UGV set: "&Inputs!B40&"." -> Years from Sep 2026 until the serving force falls below the minimum needed to hold the line. Active UGV set: Central.
A4: Scenario | B4: Aug 2026 published (yrs) | C4: v2 Base (yrs) | D4: v2 with UGVs, Combined (yrs) | E4: Runway added by UGVs (yrs) | F4: Collapse month (Base) | G4: Binding constraint (Base)
A5: Pessimistic | B5: =Inputs!B14*(1-Inputs!B24)/Inputs!B27/12 -> 1.9444444 | C5: =Dashboard!B5 -> 1.1305808 | D5: =Dashboard!E5 -> 1.337348 | E5: =Dashboard!E10 -> 0.20676712 | F5: =Dashboard!B20 -> 46661 | G5: =Dashboard!B25 -> Throughput
A6: Central | B6: =Inputs!C14*(1-Inputs!C24)/Inputs!C27/12 -> 3.5 | C6: =Dashboard!B6 -> 3.5950012 | D6: =Dashboard!E6 -> 3.9601899 | E6: =Dashboard!E11 -> 0.36518871 | F6: =Dashboard!B21 -> 47574 | G6: =Dashboard!B26 -> Pool exhausted
A7: Optimistic | B7: =Inputs!D14*(1-Inputs!D24)/Inputs!D27/12 -> 5.8333333 | C7: =Dashboard!B7 -> 8.9256217 | D7: =Dashboard!E7 -> 10.159425 | E7: =Dashboard!E12 -> 1.2338036 | F7: =Dashboard!B22 -> 49522 | G7: =Dashboard!B27 -> Pool exhausted
A10: What drains the force (Central, men/month) | B10: Men / month | C10: Share of drain | D10: Can UGVs reduce it?
A11: Irrecoverable losses (KIA, MIA, POW, disabled) | B11: =Inputs!C27 -> 12500 | C11: =B11/$B$14 -> 0.58823529 | D11: Yes — Ch1 & Ch2
A12: Net permanent AWOL / desertion | B12: =Inputs!C32 -> 6750 | C12: =B12/$B$14 -> 0.31764706 | D12: No
A13: Other discharges | B13: =Inputs!C33 -> 2000 | C13: =B13/$B$14 -> 0.094117647 | D13: No
A14: Total net drain | B14: =SUM(B11:B13) -> 21250 | C14: =SUM(C11:C13) -> 1
A16: Headline numbers for the text (Central)
A17: Total spendable pool (men) | B17: =Inputs!C13 -> 1394000
A18: Minimum force to hold 1,200 km (men) | B18: =Inputs!C22 -> 495000
A19: Loss-rate cut from UGVs by month 36 | B19: =Dashboard!B37 -> 0.15768725
A20: Runway added by UGVs, Combined (yrs) | B20: =Dashboard!E11 -> 0.36518871
A21: Runway added by UGVs, Combined (%) | B21: =Dashboard!E16 -> 0.10158236

Sheet Inputs
A1: Inputs — Project Broadcast Issue 6 (v2, Sep 2026)
A2: Blue = editable input · Black = formula · Yellow fill = judgment call with no hard public data. Evidence: Reported = official/credible public figure · Estimate = derived from reported figures · Judgment = authors' assumption.
A4: Manpower inputs | B4: Pessimistic | C4: Central | D4: Optimistic | F4: Unit | G4: Evidence | H4: Source / rationale
A5: 1. Manpower pool — lifetime stock of men who could fight (includes all future intake)
A6: Men currently serving in Defence Forces (S0) | B6: 680000 | C6: 800000 | D6: 880000 | F6: men | G6: Reported | H6: Low = IISS 2026 (~677k active). High = Zelensky, Jan 2025 (880k). Central = midpoint allowing for losses/AWOL since.
A7: Civilian men aged 25–60 in government-controlled Ukraine | B7: 4000000 | C7: 4500000 | D7: 5000000 | F7: men | G7: Estimate | H7: ~8.7M conscription-age men pre-invasion fell to ~5M by Feb 2024 (death, emigration). Excludes men abroad. Secondary source — order of magnitude.
A8: Less: reserved ('booked') workers | B8: 1300000 | C8: 1200000 | D8: 1000000 | F8: men | G8: Reported | H8: ~930k–1M booked (Deputy MoD Havryliuk, Aug 2024); +300k over the past year (Economy Minister Sobolev, Jul 2026).
A9: Less: medically unfit / legally exempt (share of remainder) | B9: 0.45 | C9: 0.4 | D9: 0.35 | F9: % | G9: Judgment | H9: Disability, carers, 3+ children, students, unfit per medical commission. No public total.
A10: → Theoretically mobilizable men | B10: =(B7-B8)*(1-B9) -> 1485000 | C10: =(C7-C8)*(1-C9) -> 1980000 | D10: =(D7-D8)*(1-D9) -> 2600000 | F10: men | G10: Formula
A11: Reachability over the war (share realistically drafted) | B11: 0.25 | C11: 0.3 | D11: 0.35 | F11: % | G11: Judgment | H11: Key judgment. Fedorov (Jan 2026): ~2M men avoiding draft notices. Police got >1.5M search requests from recruitment centres in 2026 alone.
A12: → Reachable reserve not yet in uniform (R0) | B12: =B10*B11 -> 371250 | C12: =C10*C11 -> 594000 | D12: =D10*D11 -> 910000 | F12: men | G12: Formula
A13: → Total spendable pool (S0 + R0) | B13: =B6+B12 -> 1051250 | C13: =C6+C12 -> 1394000 | D13: =D6+D12 -> 1790000 | F13: men | G13: Formula | H13: Comparable to the Aug 2026 '500k–1M pool' but built bottom-up.
A14: Memo: Aug 2026 analysis pool (superseded) | B14: 500000 | C14: 750000 | D14: 1000000 | F14: men | G14: Legacy | H14: Used only on the Bridge (Dashboard).
A16: 2. Minimum force to hold the line (collapse threshold)
A17: Active front length | B17: 1250 | C17: 1200 | D17: 1150 | F17: km | G17: Reported | H17: ~1,200 km of active front (Defense News, Apr 2026).
A18: Line troops per km of front (incl. rotation) | B18: 140 | C18: 125 | D18: 110 | F18: men/km | G18: Judgment | H18: Troops in positions + rotation reserve per km. Russia attacks with small, constant assault groups ('thousand cuts'), which forces a continuous line.
A19: → Line requirement | B19: =B17*B18 -> 175000 | C19: =C17*C18 -> 150000 | D19: =D17*D18 -> 126500 | F19: men | G19: Formula | H19: UGV headcount replacement (Ch2) reduces this portion only.
A20: Support/rear troops per line soldier | B20: 2.4 | C20: 2.3 | D20: 2.2 | F20: ratio | G20: Judgment | H20: Drone units, artillery, logistics, air defence, training, border, HQ.
A21: → Support requirement | B21: =B19*B20 -> 420000 | C21: =C19*C20 -> 345000 | D21: =D19*D20 -> 278300 | F21: men | G21: Formula
A22: → Minimum total force before line fails | B22: =B19+B21 -> 595000 | C22: =C19+C21 -> 495000 | D22: =D19+D21 -> 404800 | F22: men | G22: Formula | H22: Absolute threshold, independent of pool size (fixes Aug 2026 floor = 30% of pool).
A23: → Spendable margin (pool − minimum force) | B23: =B13-B22 -> 456250 | C23: =C13-C22 -> 899000 | D23: =D13-D22 -> 1385200 | F23: men | G23: Formula
A24: Memo: Aug 2026 collapse floor (% of pool, superseded) | B24: 0.3 | C24: 0.3 | D24: 0.3 | F24: % | G24: Legacy | H24: Used only on the Bridge.
A26: 3. Monthly flows
A27: Irrecoverable losses / month (KIA, MIA, POW, permanently disabled) | B27: 15000 | C27: 12500 | D27: 10000 | F27: men/mo | G27: Estimate | H27: Dutch MIVD (Apr 2026): ~500k Ukrainian permanent losses since Feb 2022 ≈ 10k/mo average; intensity higher in 2025–26. CSIS (Jan 2026): 100–140k killed to Dec 2025.
A28: Loss-rate drift per year (intensity trend) | B28: 0.05 | C28: 0 | D28: -0.05 | F28: %/yr | G28: Judgment | H28: + = Russian pressure rising. Russia's force grew only ~11k in H1 2026 and contract recruitment fell ~1/3 (Syrskyi, Jul 2026).
A29: Loss elasticity to force size | B29: 0 | C29: 0.25 | D29: 0.5 | F29: exponent | G29: Judgment | H29: 0 = losses fixed by Russian pressure; 1 = losses fall 1:1 as the force shrinks. The line is held at minimum manning, so elasticity is low.
A30: AWOL / desertion cases per month (gross) | B30: 18000 | C30: 15000 | D30: 12000 | F30: men/mo | G30: Reported | H30: Prosecutor General: 161,461 AWOL + 21,479 desertion cases Jan–Oct 2025 (~18k/mo). Statistics classified since Nov 2025.
A31: Share of AWOL who return to service | B31: 0.4 | C31: 0.55 | D31: 0.65 | F31: % | G31: Judgment | H31: Return-without-prosecution pathway (draft law 16074, Sep 2026). Fedorov: ~200k AWOL at a point in time (Jan 2026).
A32: → Net permanent AWOL loss / month | B32: =B30*(1-B31) -> 10800 | C32: =C30*(1-C31) -> 6750 | D32: =D30*(1-D31) -> 4200 | F32: men/mo | G32: Formula | H32: Scales with force size in the Engine.
A33: Other discharges / month (age-out, non-combat medical, demobilization) | B33: 2500 | C33: 2000 | D33: 1500 | F33: men/mo | G33: Judgment
A34: → Net monthly drain at start | B34: =B27+B32+B33 -> 28300 | C34: =C27+C32+C33 -> 21250 | D34: =D27+D32+D33 -> 15700 | F34: men/mo | G34: Formula
A35: → Gross monthly outflow (cross-check) | B35: =B27+B30+B33 -> 35500 | C35: =C27+C30+C33 -> 29500 | D35: =D27+D30+D33 -> 23500 | F35: men/mo | G35: Formula | H35: Should be close to Budanov's 30k/mo 'needed to maintain what we have' (Aug 2026). See Checks tab.
A36: Mobilization throughput capacity / month | B36: 22000 | C36: 30000 | D36: 34000 | F36: men/mo | G36: Reported | H36: SCEEUS (Dec 2025): 17–24k/mo. Zelensky (Feb 2026): 30–34k/mo. Budanov (Aug 2026): ≥30k/mo needed.
A39: 4. UGV assumptions (choose set in B40) | B39: Low | C39: Central | D39: High | E39: Active | F39: Unit | G39: Evidence | H39: Source / rationale
A40: Active UGV assumption set → | B40: Central | E40: =MATCH(B40,B39:D39,0) -> 2 | F40: index | G40: Switch | H40: Dropdown: Low / Central / High. Applies to all manpower scenarios.
A41: Loss share: logistics, resupply & casevac tasks | B41: 0.2 | C41: 0.25 | D41: 0.3 | E41: {=INDEX(B41:D41,$E$40)} -> 0.25 | F41: % of losses | G41: Judgment | H41: No public split. Resupply/evac runs through the drone kill zone.
A42: Loss share: combat tasks (holding positions, assault) | B42: =1-B41 -> 0.8 | C42: =1-C41 -> 0.75 | D42: =1-D41 -> 0.7 | E42: {=INDEX(B42:D42,$E$40)} -> 0.75 | F42: % of losses | G42: Formula | H42: Residual.
A43: UGV missions / month today | B43: 24000 | C43: 24000 | D43: 24000 | E43: {=INDEX(B43:D43,$E$40)} -> 24000 | F43: missions/mo | G43: Reported | H43: MoD data via Defense Post: 19,969 missions in Jul 2026; 15,729 on Aug 1–20 (~24k/mo pace).
A44: Logistics coverage today (share of frontline logistics runs) | B44: 0.2 | C44: 0.2 | D44: 0.2 | E44: {=INDEX(B44:D44,$E$40)} -> 0.2 | F44: % | G44: Judgment | H44: Contested: an industry source (Ratel Robotics, Apr 2026) claims ~80%. We use 20% because ~800 missions/day across 1,200 km is thin. Stress-test this.
A45: → Implied total logistics runs / month at 100% coverage | B45: =B43/B44 -> 120000 | C45: =C43/C44 -> 120000 | D45: =D43/D44 -> 120000 | E45: {=INDEX(B45:D45,$E$40)} -> 120000 | F45: runs/mo | G45: Formula | H45: Anchors the supply check.
...

Sheet Engine
A1: Engine — month-by-month stock-flow (do not edit). Serving force S and untapped reserve R; collapse when S < minimum force.
A2: Common UGV columns use the ACTIVE UGV set (Inputs!B40). Blocks = case × manpower scenario. Month 0 = Inputs!B67.
C3: Common UGV drivers | M3: Base (UGVs frozen at today) — Pessimistic | V3: Base (UGVs frozen at today) — Central | AE3: Base (UGVs frozen at today) — Optimistic | AN3: Ch1: loss-rate — Pessimistic | AW3: Ch1: loss-rate — Central | BF3: Ch1: loss-rate — Optimistic | BO3: Ch2: headcount — Pessimistic | BX3: Ch2: headcount — Central | CG3: Ch2: headcount — Optimistic | CP3: Combined — Pessimistic | CY3: Combined — Central | DH3: Combined — Optimistic
A4: Month | B4: Date | C4: Log cov (ramp) | D4: Log cov (supply max) | E4: Log cov (effective) | F4: Combat cov | G4: Ch1 loss mult (vs today) | H4: Headcount repl h | I4: RU UGV pressure | J4: UGV crew (incremental) | K4: Supply-bound? | M4: Intake | N4: Loss | O4: AWOL net | P4: Discharge | Q4: Serving S | R4: Reserve R | S4: Min force | T4: Gap S−min | U4: Broken? | V4: Intake | W4: Loss | X4: AWOL net | Y4: Discharge | Z4: Serving S | AA4: Reserve R | AB4: Min force | AC4: Gap S−min | AD4: Broken? | AE4: Intake | AF4: Loss | AG4: AWOL net | AH4: Discharge | AI4: Serving S | AJ4: Reserve R | AK4: Min force | AL4: Gap S−min | AM4: Broken? | AN4: Intake | AO4: Loss | AP4: AWOL net | AQ4: Discharge | AR4: Serving S | AS4: Reserve R | AT4: Min force | AU4: Gap S−min | AV4: Broken? | AW4: Intake | AX4: Loss | AY4: AWOL net | AZ4: Discharge | BA4: Serving S | BB4: Reserve R | BC4: Min force | BD4: Gap S−min | BE4: Broken? | BF4: Intake | BG4: Loss | BH4: AWOL net | BI4: Discharge | BJ4: Serving S | BK4: Reserve R | BL4: Min force | BM4: Gap S−min | BN4: Broken? | BO4: Intake | BP4: Loss | BQ4: AWOL net | BR4: Discharge | BS4: Serving S | BT4: Reserve R | BU4: Min force | BV4: Gap S−min | BW4: Broken? | BX4: Intake | BY4: Loss | BZ4: AWOL net | CA4: Discharge | CB4: Serving S | CC4: Reserve R | CD4: Min force | CE4: Gap S−min | CF4: Broken? | CG4: Intake | CH4: Loss | CI4: AWOL net | CJ4: Discharge | CK4: Serving S | CL4: Reserve R | CM4: Min force | CN4: Gap S−min | CO4: Broken? | CP4: Intake | CQ4: Loss | CR4: AWOL net | CS4: Discharge | CT4: Serving S | CU4: Reserve R | CV4: Min force | CW4: Gap S−min | CX4: Broken? | CY4: Intake | CZ4: Loss | DA4: AWOL net | DB4: Discharge | DC4: Serving S | DD4: Reserve R | DE4: Min force | DF4: Gap S−min | DG4: Broken? | DH4: Intake | DI4: Loss | DJ4: AWOL net | DK4: Discharge | DL4: Serving S | DM4: Reserve R | DN4: Min force | DO4: Gap S−min | DP4: Broken?
A5: 0 | B5: =EDATE(Inputs!$B$67,$A5) -> 46266 | C5: =IF(Inputs!$E$47<=0,Inputs!$E$46,Inputs!$E$44+(Inputs!$E$46-Inputs!$E$44)*MIN($A5/Inputs!$E$47,1)) -> 0.2 | D5: =MIN(Inputs!$E$57,Inputs!$E$55*(1+Inputs!$E$56)^($A5/12))*Inputs!$E$58*(1+Inputs!$E$59)^($A5/12)/Inputs!$E$45 -> 0.42 | E5: =MAX(Inputs!$E$44,MIN(C5,D5)) -> 0.2 | F5: =IF(Inputs!$E$50<=0,Inputs!$E$49,Inputs!$E$48+(Inputs!$E$49-Inputs!$E$48)*MIN($A5/Inputs!$E$50,1)) -> 0.02 | G5: =(Inputs!$E$41*(1-E5*Inputs!$E$51)+Inputs!$E$42*(1-F5*Inputs!$E$51))/(Inputs!$E$41*(1-Inputs!$E$44*Inputs!$E$51)+Inputs!$E$42*(1-Inputs!$E$48*Inputs!$E$51)) -> 1 | H5: =IF(Inputs!$E$53<=0,Inputs!$E$52,Inputs!$E$52*MIN($A5/Inputs!$E$53,1)) -> 0 | I5: =IF(Inputs!$E$64<=0,Inputs!$E$63,Inputs!$E$62+(Inputs!$E$63-Inputs!$E$62)*MIN($A5/Inputs!$E$64,1)) -> 0 | J5: =(E5-Inputs!$E$44)*Inputs!$E$45/Inputs!$E$60*Inputs!$E$61 -> 0 | K5: =IF(D5<C5,1,0) -> 0 | M5: 0 | N5: 0 | O5: 0 | P5: 0 | Q5: =Inputs!$B$6 -> 680000 | R5: =Inputs!$B$12 -> 371250 | S5: =Inputs!$B$19*(1-Inputs!$C$70*$H5)+Inputs!$B$21+Inputs!$B$70*$J5 -> 595000 | T5: =Q5-S5 -> 85000 | U5: =IF(T5<0,1,0) -> 0 | V5: 0 | W5: 0 | X5: 0 | Y5: 0 | Z5: =Inputs!$C$6 -> 800000 | AA5: =Inputs!$C$12 -> 594000 | AB5: =Inputs!$C$19*(1-Inputs!$C$70*$H5)+Inputs!$C$21+Inputs!$B$70*$J5 -> 495000 | AC5: =Z5-AB5 -> 305000 | AD5: =IF(AC5<0,1,0) -> 0 | AE5: 0 | AF5: 0 | AG5: 0 | AH5: 0 | AI5: =Inputs!$D$6 -> 880000 | AJ5: =Inputs!$D$12 -> 910000 | AK5: =Inputs!$D$19*(1-Inputs!$C$70*$H5)+Inputs!$D$21+Inputs!$B$70*$J5 -> 404800 | AL5: =AI5-AK5 -> 475200 | AM5: =IF(AL5<0,1,0) -> 0 | AN5: 0 | AO5: 0 | AP5: 0 | AQ5: 0 | AR5: =Inputs!$B$6 -> 680000 | AS5: =Inputs!$B$12 -> 371250 | AT5: =Inputs!$B$19*(1-Inputs!$C$71*$H5)+Inputs!$B$21+Inputs!$B$71*$J5 -> 595000 | AU5: =AR5-AT5 -> 85000 | AV5: =IF(AU5<0,1,0) -> 0 | AW5: 0 | AX5: 0 | AY5: 0 | AZ5: 0 | BA5: =Inputs!$C$6 -> 800000 | BB5: =Inputs!$C$12 -> 594000 | BC5: =Inputs!$C$19*(1-Inputs!$C$71*$H5)+Inputs!$C$21+Inputs!$B$71*$J5 -> 495000 | BD5: =BA5-BC5 -> 305000 | BE5: =IF(BD5<0,1,0) -> 0 | BF5: 0 | BG5: 0 | BH5: 0 | BI5: 0 | BJ5: =Inputs!$D$6 -> 880000 | BK5: =Inputs!$D$12 -> 910000 | BL5: =Inputs!$D$19*(1-Inputs!$C$71*$H5)+Inputs!$D$21+Inputs!$B$71*$J5 -> 404800 | BM5: =BJ5-BL5 -> 475200 | BN5: =IF(BM5<0,1,0) -> 0 | BO5: 0 | BP5: 0 | BQ5: 0 | BR5: 0 | BS5: =Inputs!$B$6 -> 680000 | BT5: =Inputs!$B$12 -> 371250 | BU5: =Inputs!$B$19*(1-Inputs!$C$72*$H5)+Inputs!$B$21+Inputs!$B$72*$J5 -> 595000 | BV5: =BS5-BU5 -> 85000 | BW5: =IF(BV5<0,1,0) -> 0 | BX5: 0 | BY5: 0 | BZ5: 0 | CA5: 0 | CB5: =Inputs!$C$6 -> 800000 | CC5: =Inputs!$C$12 -> 594000 | CD5: =Inputs!$C$19*(1-Inputs!$C$72*$H5)+Inputs!$C$21+Inputs!$B$72*$J5 -> 495000 | CE5: =CB5-CD5 -> 305000 | CF5: =IF(CE5<0,1,0) -> 0 | CG5: 0 | CH5: 0 | CI5: 0 | CJ5: 0 | CK5: =Inputs!$D$6 -> 880000 | CL5: =Inputs!$D$12 -> 910000 | CM5: =Inputs!$D$19*(1-Inputs!$C$72*$H5)+Inputs!$D$21+Inputs!$B$72*$J5 -> 404800 | CN5: =CK5-CM5 -> 475200 | CO5: =IF(CN5<0,1,0) -> 0 | CP5: 0 | CQ5: 0 | CR5: 0 | CS5: 0 | CT5: =Inputs!$B$6 -> 680000 | CU5: =Inputs!$B$12 -> 371250 | CV5: =Inputs!$B$19*(1-Inputs!$C$73*$H5)+Inputs!$B$21+Inputs!$B$73*$J5 -> 595000 | CW5: =CT5-CV5 -> 85000 | CX5: =IF(CW5<0,1,0) -> 0 | CY5: 0 | CZ5: 0 | DA5: 0 | DB5: 0 | DC5: =Inputs!$C$6 -> 800000 | DD5: =Inputs!$C$12 -> 594000 | DE5: =Inputs!$C$19*(1-Inputs!$C$73*$H5)+Inputs!$C$21+Inputs!$B$73*$J5 -> 495000 | DF5: =DC5-DE5 -> 305000 | DG5: =IF(DF5<0,1,0) -> 0 | DH5: 0 | DI5: 0 | DJ5: 0 | DK5: 0 | DL5: =Inputs!$D$6 -> 880000 | DM5: =Inputs!$D$12 -> 910000 | DN5: =Inputs!$D$19*(1-Inputs!$C$73*$H5)+Inputs!$D$21+Inputs!$B$73*$J5 -> 404800 | DO5: =DL5-DN5 -> 475200 | DP5: =IF(DO5<0,1,0) -> 0
A6: 1 | B6: =EDATE(Inputs!$B$67,$A6) -> 46296 | C6: =IF(Inputs!$E$47<=0,Inputs!$E$46,Inputs!$E$44+(Inputs!$E$46-Inputs!$E$44)*MIN($A6/Inputs!$E$47,1)) -> 0.22083333 | D6: =MIN(Inputs!$E$57,Inputs!$E$55*(1+Inputs!$E$56)^($A6/12))*Inputs!$E$58*(1+Inputs!$E$59)^($A6/12)/Inputs!$E$45 -> 0.43194319 | E6: =MAX(Inputs!$E$44,MIN(C6,D6)) -> 0.22083333 | F6: =IF(Inputs!$E$50<=0,Inputs!$E$49,Inputs!$E$48+(Inputs!$E$49-Inputs!$E$48)*MIN($A6/Inputs!$E$50,1)) -> 0.022777778 | G6: =(Inputs!$E$41*(1-E6*Inputs!$E$51)+Inputs!$E$42*(1-F6*Inputs!$E$51))/(Inputs!$E$41*(1-Inputs!$E$44*Inputs!$E$51)+Inputs!$E$42*(1-Inputs!$E$48*Inputs!$E$51)) -> 0.99425099 | H6: =IF(Inputs!$E$53<=0,Inputs!$E$52,Inputs!$E$52*MIN($A6/Inputs!$E$53,1)) -> 0.0020833333 | I6: =IF(Inputs!$E$64<=0,Inputs!$E$63,Inputs!$E$62+(Inputs!$E$63-Inputs!$E$62)*MIN($A6/Inputs!$E$64,1)) -> 0.00125 | J6: =(E6-Inputs!$E$44)*Inputs!$E$45/Inputs!$E$60*Inputs!$E$61 -> 250 | K6: =IF(D6<C6,1,0) -> 0 | M6: =MAX(0,MIN(Inputs!$B$36,R5,N6+O6+P6+Inputs!$B$6-Q5)) -> 22000 | N6: =Inputs!$B$27*(1+Inputs!$B$28)^($A6/12)*IF(Inputs!$B$70=1,$G6,1)*(1-Inputs!$C$70*$H6*(1-Inputs!$E$54*Inputs!$B$70))*(1+$I6)*IF(Inputs!$B$29=0,1,(MAX(Q5,0)/Inputs!$B$6)^Inputs!$B$29) -> 15079.938 | O6: =Inputs!$B$32*Q5/Inputs!$B$6 -> 10800 | P6: =Inputs!$B$33 -> 2500 | Q6: =MAX(Q5+M6-N6-O6-P6,0) -> 673620.06 | R6: =R5-M6 -> 349250 | S6: =Inputs!$B$19*(1-Inputs!$C$70*$H6)+Inputs!$B$21+Inputs!$B$70*$J6 -> 595000 | T6: =Q6-S6 -> 78620.062 | U6: =IF(T6<0,1,0) -> 0 | V6: =MAX(0,MIN(Inputs!$C$36,AA5,W6+X6+Y6+Inputs!$C$6-Z5)) -> 21265.625 | W6: =Inputs!$C$27*(1+Inputs!$C$28)^($A6/12)*IF(Inputs!$B$70=1,$G6,1)*(1-Inputs!$C$70*$H6*(1-Inputs!$E$54*Inputs!$B$70))*(1+$I6)*IF(Inputs!$C$29=0,1,(MAX(Z5,0)/Inputs!$C$6)^Inputs!$C$29) -> 12515.625 | X6: =Inputs!$C$32*Z5/Inputs!$C$6 -> 6750 | Y6: =Inputs!$C$33 -> 2000 | Z6: =MAX(Z5+V6-W6-X6-Y6,0) -> 800000 | AA6: =AA5-V6 -> 572734.38 | AB6: =Inputs!$C$19*(1-Inputs!$C$70*$H6)+Inputs!$C$21+Inputs!$B$70*$J6 -> 495000 | AC6: =Z6-AB6 -> 305000 | AD6: =IF(AC6<0,1,0) -> 0 | AE6: =MAX(0,MIN(Inputs!$D$36,AJ5,AF6+AG6+AH6+Inputs!$D$6-AI5)) -> 15669.793 | AF6: =Inputs!$D$27*(1+Inputs!$D$28)^($A6/12)*IF(Inputs!$B$70=1,$G6,1)*(1-Inputs!$C$70*$H6*(1-Inputs!$E$54*Inputs!$B$70))*(1+$I6)*IF(Inputs!$D$29=0,1,(MAX(AI5,0)/Inputs!$D$6)^Inputs!$D$29) -> 9969.7935 | AG6: =Inputs!$D$32*AI5/Inputs!$D$6 -> 4200 | AH6: =Inputs!$D$33 -> 1500 | AI6: =MAX(AI5+AE6-AF6-AG6-AH6,0) -> 880000 | AJ6: =AJ5-AE6 -> 894330.21 | AK6: =Inputs!$D$19*(1-Inputs!$C$70*$H6)+Inputs!$D$21+Inputs!$B$70*$J6 -> 404800 | AL6: =AI6-AK6 -> 475200 | AM6: =IF(AL6<0,1,0) -> 0 | AN6: =MAX(0,MIN(Inputs!$B$36,AS5,AO6+AP6+AQ6+Inputs!$B$6-AR5)) -> 22000 | AO6: =Inputs!$B$27*(1+Inputs!$B$28)^($A6/12)*IF(Inputs!$B$71=1,$G6,1)*(1-Inputs!$C$71*$H6*(1-Inputs!$E$54*Inputs!$B$71))*(1+$I6)*IF(Inputs!$B$29=0,1,(MAX(AR5,0)/Inputs!$B$6)^Inputs!$B$29) -> 14993.243 | AP6: =Inputs!$B$32*AR5/Inputs!$B$6 -> 10800 | AQ6: =Inputs!$B$33 -> 2500 | AR6: =MAX(AR5+AN6-AO6-AP6-AQ6,0) -> 673706.76 | AS6: =AS5-AN6 -> 349250 | AT6: =Inputs!$B$19*(1-Inputs!$C$71*$H6)+Inputs!$B$21+Inputs!$B$71*$J6 -> 595250 | AU6: =AR6-AT6 -> 78456.757 | AV6: =IF(AU6<0,1,0) -> 0 | AW6: =MAX(0,MIN(Inputs!$C$36,BB5,AX6+AY6+AZ6+Inputs!$C$6-BA5)) -> 21193.672 | AX6: =Inputs!$C$27*(1+Inputs!$C$28)^($A6/12)*IF(Inputs!$B$71=1,$G6,1)*(1-Inputs!$C$71*$H6*(1-Inputs!$E$54*Inputs!$B$71))*(1+$I6)*IF(Inputs!$C$29=0,1,(MAX(BA5,0)/Inputs!$C$6)^Inputs!$C$29) -> 12443.672 | AY6: =Inputs!$C$32*BA5/Inputs!$C$6 -> 6750 | AZ6: =Inputs!$C$33 -> 2000 | BA6: =MAX(BA5+AW6-AX6-AY6-AZ6,0) -> 800000 | BB6: =BB5-AW6 -> 572806.33 | BC6: =Inputs!$C$19*(1-Inputs!$C$71*$H6)+Inputs!$C$21+Inputs!$B$71*$J6 -> 495250 | BD6: =BA6-BC6 -> 304750 | BE6: =IF(BD6<0,1,0) -> 0 | BF6: =MAX(0,MIN(Inputs!$D$36,BK5,BG6+BH6+BI6+Inputs!$D$6-BJ5)) -> 15612.477 | BG6: =Inputs!$D$27*(1+Inputs!$D$28)^($A6/12)*IF(Inputs!$B$71=1,$G6,1)*(1-Inputs!$C$71*$H6*(1-Inputs!$E$54*Inputs!$B$71))*(1+$I6)*IF(Inputs!$D$29=0,1,(MAX(BJ5,0)/Inputs!$D$6)^Inputs!$D$29) -> 9912.477 | BH6: =Inputs!$D$32*BJ5/Inputs!$D$6 -> 4200 | BI6: =Inputs!$D$33 -> 1500 | BJ6: =MAX(BJ5+BF6-BG6-BH6-BI6,0) -> 880000 | BK6: =BK5-BF6 -> 894387.52 | BL6: =Inputs!$D$19*(1-Inputs!$C$71*$H6)+Inputs!$D$21+Inputs!$B$71*$J6 -> 405050 | BM6: =BJ6-BL6 -> 474950 | BN6: =IF(BM6<0,1,0) -> 0 | BO6: =MAX(0,MIN(Inputs!$B$36,BT5,BP6+BQ6+BR6+Inputs!$B$6-BS5)) -> 22000 | BP6: =Inputs!$B$27*(1+Inputs!$B$28)^($A6/12)*IF(Inputs!$B$72=1,$G6,1)*(1-Inputs!$C$72*$H6*(1-Inputs!$E$54*Inputs!$B$72))*(1+$I6)*IF(Inputs!$B$29=0,1,(MAX(BS5,0)/Inputs!$B$6)^Inputs!$B$29) -> 15048.522 | BQ6: =Inputs!$B$32*BS5/Inputs!$B$6 -> 10800 | BR6: =Inputs!$B$33 -> 2500 | BS6: =MAX(BS5+BO6-BP6-BQ6-BR6,0) -> 673651.48 | BT6: =BT5-BO6 -> 349250 | BU6: =Inputs!$B$19*(1-Inputs!$C$72*$H6)+Inputs!$B$21+Inputs!$B$72*$J6 -> 594635.42 | BV6: =BS6-BU6 -> 79016.062 | BW6: =IF(BV6<0,1,0) -> 0 | BX6: =MAX(0,MIN(Inputs!$C$36,CC5,BY6+BZ6+CA6+Inputs!$C$6-CB5)) -> 21239.551 | BY6: =Inputs!$C$27*(1+Inputs!$C$28)^($A6/12)*IF(Inputs!$B$72=1,$G6,1)*(1-Inputs!$C$72*$H6*(1-Inputs!$E$54*Inputs!$B$72))*(1+$I6)*IF(Inputs!$C$29=0,1,(MAX(CB5,0)/Inputs!$C$6)^Inputs!$C$29) -> 12489.551 | BZ6: =Inputs!$C$32*CB5/Inputs!$C$6 -> 6750 | CA6: =Inputs!$C$33 -> 2000 | CB6: =MAX(CB5+BX6-BY6-BZ6-CA6,0) -> 800000 | CC6: =CC5-BX6 -> 572760.45 | CD6: =Inputs!$C$19*(1-Inputs!$C$72*$H6)+Inputs!$C$21+Inputs!$B$72*$J6 -> 494687.5 | CE6: =CB6-CD6 -> 305312.5 | CF6: =IF(CE6<0,1,0) -> 0 | CG6: =MAX(0,MIN(Inputs!$D$36,CL5,CH6+CI6+CJ6+Inputs!$D$6-CK5)) -> 15649.023 | CH6: =Inputs!$D$27*(1+Inputs!$D$28)^($A6/12)*IF(Inputs!$B$72=1,$G6,1)*(1-Inputs!$C$72*$H6*(1-Inputs!$E$54*Inputs!$B$72))*(1+$I6)*IF(Inputs!$D$29=0,1,(MAX(CK5,0)/Inputs!$D$6)^Inputs!$D$29) -> 9949.0231 | CI6: =Inputs!$D$32*CK5/Inputs!$D$6 -> 4200 | CJ6: =Inputs!$D$33 -> 1500 | CK6: =MAX(CK5+CG6-CH6-CI6-CJ6,0) -> 880000 | CL6: =CL5-CG6 -> 894350.98 | CM6: =Inputs!$D$19*(1-Inputs!$C$72*$H6)+Inputs!$D$21+Inputs!$B$72*$J6 -> 404536.46 | CN6: =CK6-CM6 -> 475463.54 | CO6: =IF(CN6<0,1,0) -> 0 | CP6: =MAX(0,MIN(Inputs!$B$36,CU5,CQ6+CR6+CS6+Inputs!$B$6-CT5)) -> 22000 | CQ6: =Inputs!$B$27*(1+Inputs!$B$28)^($A6/12)*IF(Inputs!$B$73=1,$G6,1)*(1-Inputs!$C$73*$H6*(1-Inputs!$E$54*Inputs!$B$73))*(1+$I6)*IF(Inputs!$B$29=0,1,(MAX(CT5,0)/Inputs!$B$6)^Inputs!$B$29) -> 14977.626 | CR6: =Inputs!$B$32*CT5/Inputs!$B$6 -> 10800 | CS6: =Inputs!$B$33 -> 2500 | CT6: =MAX(CT5+CP6-CQ6-CR6-CS6,0) -> 673722.37 | CU6: =CU5-CP6 -> 349250 | CV6: =Inputs!$B$19*(1-Inputs!$C$73*$H6)+Inputs!$B$21+Inputs!$B$73*$J6 -> 594885.42 | CW6: =CT6-CV6 -> 78836.958 | CX6: =IF(CW6<0,1,0) -> 0 | CY6: =MAX(0,MIN(Inputs!$C$36,DD5,CZ6+DA6+DB6+Inputs!$C$6-DC5)) -> 21180.71 | CZ6: =Inputs!$C$27*(1+Inputs!$C$28)^($A6/12)*IF(Inputs!$B$73=1,$G6,1)*(1-Inputs!$C$73*$H6*(1-Inputs!$E$54*Inputs!$B$73))*(1+$I6)*IF(Inputs!$C$29=0,1,(MAX(DC5,0)/Inputs!$C$6)^Inputs!$C$29) -> 12430.71 | DA6: =Inputs!$C$32*DC5/Inputs!$C$6 -> 6750 | DB6: =Inputs!$C$33 -> 2000 | DC6: =MAX(DC5+CY6-CZ6-DA6-DB6,0) -> 800000 | DD6: =DD5-CY6 -> 572819.29 | DE6: =Inputs!$C$19*(1-Inputs!$C$73*$H6)+Inputs!$C$21+Inputs!$B$73*$J6 -> 494937.5 | DF6: =DC6-DE6 -> 305062.5 | DG6: =IF(DF6<0,1,0) -> 0 | DH6: =MAX(0,MIN(Inputs!$D$36,DM5,DI6+DJ6+DK6+Inputs!$D$6-DL5)) -> 15602.152 | DI6: =Inputs!$D$27*(1+Inputs!$D$28)^($A6/12)*IF(Inputs!$B$73=1,$G6,1)*(1-Inputs!$C$73*$H6*(1-Inputs!$E$54*Inputs!$B$73))*(1+$I6)*IF(Inputs!$D$29=0,1,(MAX(DL5,0)/Inputs!$D$6)^Inputs!$D$29) -> 9902.1515 | DJ6: =Inputs!$D$32*DL5/Inputs!$D$6 -> 4200 | DK6: =Inputs!$D$33 -> 1500 | DL6: =MAX(DL5+DH6-DI6-DJ6-DK6,0) -> 880000 | DM6: =DM5-DH6 -> 894397.85 | DN6: =Inputs!$D$19*(1-Inputs!$C$73*$H6)+Inputs!$D$21+Inputs!$B$73*$J6 -> 404786.46 | DO6: =DL6-DN6 -> 475213.54 | DP6: =IF(DO6<0,1,0) -> 0
A7: 2 | B7: =EDATE(Inputs!$B$67,$A7) -> 46327 | C7: =IF(Inputs!$E$47<=0,Inputs!$E$46,Inputs!$E$44+(Inputs!$E$46-Inputs!$E$44)*MIN($A7/Inputs!$E$47,1)) -> 0.24166667 | D7: =MIN(Inputs!$E$57,Inputs!$E$55*(1+Inputs!$E$56)^($A7/12))*Inputs!$E$58*(1+Inputs!$E$59)^($A7/12)/Inputs!$E$45 -> 0.44422599 | E7: =MAX(Inputs!$E$44,MIN(C7,D7)) -> 0.24166667 | F7: =IF(Inputs!$E$50<=0,Inputs!$E$49,Inputs!$E$48+(Inputs!$E$49-Inputs!$E$48)*MIN($A7/Inputs!$E$50,1)) -> 0.025555556 | G7: =(Inputs!$E$41*(1-E7*Inputs!$E$51)+Inputs!$E$42*(1-F7*Inputs!$E$51))/(Inputs!$E$41*(1-Inputs!$E$44*Inputs!$E$51)+Inputs!$E$42*(1-Inputs!$E$48*Inputs!$E$51)) -> 0.98850197 | H7: =IF(Inputs!$E$53<=0,Inputs!$E$52,Inputs!$E$52*MIN($A7/Inputs!$E$53,1)) -> 0.0041666667 | I7: =IF(Inputs!$E$64<=0,Inputs!$E$63,Inputs!$E$62+(Inputs!$E$63-Inputs!$E$62)*MIN($A7/Inputs!$E$64,1)) -> 0.0025 | J7: =(E7-Inputs!$E$44)*Inputs!$E$45/Inputs!$E$60*Inputs!$E$61 -> 500 | K7: =IF(D7<C7,1,0) -> 0 | M7: =MAX(0,MIN(Inputs!$B$36,R6,N7+O7+P7+Inputs!$B$6-Q6)) -> 22000 | N7: =Inputs!$B$27*(1+Inputs!$B$28)^($A7/12)*IF(Inputs!$B$70=1,$G7,1)*(1-Inputs!$C$70*$H7*(1-Inputs!$E$54*Inputs!$B$70))*(1+$I7)*IF(Inputs!$B$29=0,1,(MAX(Q6,0)/Inputs!$B$6)^Inputs!$B$29) -> 15160.279 | O7: =Inputs!$B$32*Q6/Inputs!$B$6 -> 10698.672 | P7: =Inputs!$B$33 -> 2500 | Q7: =MAX(Q6+M7-N7-O7-P7,0) -> 667261.11 | R7: =R6-M7 -> 327250 | S7: =Inputs!$B$19*(1-Inputs!$C$70*$H7)+Inputs!$B$21+Inputs!$B$70*$J7 -> 595000 | T7: =Q7-S7 -> 72261.111 | U7: =IF(T7<0,1,0) -> 0 | V7: =MAX(0,MIN(Inputs!$C$36,AA6,W7+X7+Y7+Inputs!$C$6-Z6)) -> 21281.25 | W7: =Inputs!$C$27*(1+Inputs!$C$28)^($A7/12)*IF(Inputs!$B$70=1,$G7,1)*(1-Inputs!$C$70*$H7*(1-Inputs!$E$54*Inputs!$B$70))*(1+$I7)*IF(Inputs!$C$29=0,1,(MAX(Z6,0)/Inputs!$C$6)^Inputs!$C$29) -> 12531.25 | X7: =Inputs!$C$32*Z6/Inputs!$C$6 -> 6750 | Y7: =Inputs!$C$33 -> 2000 | Z7: =MAX(Z6+V7-W7-X7-Y7,0) -> 800000 | AA7: =AA6-V7 -> 551453.12 | AB7: =Inputs!$C$19*(1-Inputs!$C$70*$H7)+Inputs!$C$21+Inputs!$B$70*$J7 -> 495000 | AC7: =Z7-AB7 -> 305000 | AD7: =IF(AC7<0,1,0) -> 0 | AE7: =MAX(0,MIN(Inputs!$D$36,AJ6,AF7+AG7+AH7+Inputs!$D$6-AI6)) -> 15639.663 | AF7: =Inputs!$D$27*(1+Inputs!$D$28)^($A7/12)*IF(Inputs!$B$70=1,$G7,1)*(1-Inputs!$C$70*$H7*(1-Inputs!$E$54*Inputs!$B$70))*(1+$I7)*IF(Inputs!$D$29=0,1,(MAX(AI6,0)/Inputs!$D$6)^Inputs!$D$29) -> 9939.6627 | AG7: =Inputs!$D$32*AI6/Inputs!$D$6 -> 4200 | AH7: =Inputs!$D$33 -> 1500 | AI7: =MAX(AI6+AE7-AF7-AG7-AH7,0) -> 880000 | AJ7: =AJ6-AE7 -> 878690.54 | AK7: =Inputs!$D$19*(1-Inputs!$C$70*$H7)+Inputs!$D$21+Inputs!$B$70*$J7 -> 404800 | AL7: =AI7-AK7 -> 475200 | AM7: =IF(AL7<0,1,0) -> 0 | AN7: =MAX(0,MIN(Inputs!$B$36,AS6,AO7+AP7+AQ7+Inputs!$B$6-AR6)) -> 22000 | AO7: =Inputs!$B$27*(1+Inputs!$B$28)^($A7/12)*IF(Inputs!$B$71=1,$G7,1)*(1-Inputs!$C$71*$H7*(1-Inputs!$E$54*Inputs!$B$71))*(1+$I7)*IF(Inputs!$B$29=0,1,(MAX(AR6,0)/Inputs!$B$6)^Inputs!$B$29) -> 14985.966 | AP7: =Inputs!$B$32*AR6/Inputs!$B$6 -> 10700.048 | AQ7: =Inputs!$B$33 -> 2500 | AR7: =MAX(AR6+AN7-AO7-AP7-AQ7,0) -> 667520.74 | AS7: =AS6-AN7 -> 327250 | AT7: =Inputs!$B$19*(1-Inputs!$C$71*$H7)+Inputs!$B$21+Inputs!$B$71*$J7 -> 595500 | AU7: =AR7-AT7 -> 72020.743 | AV7: =IF(AU7<0,1,0) -> 0 | AW7: =MAX(0,MIN(Inputs!$C$36,BB6,AX7+AY7+AZ7+Inputs!$C$6-BA6)) -> 21137.165 | AX7: =Inputs!$C$27*(1+Inputs!$C$28)^($A7/12)*IF(Inputs!$B$71=1,$G7,1)*(1-Inputs!$C$71*$H7*(1-Inputs!$E$54*Inputs!$B$71))*(1+$I7)*IF(Inputs!$C$29=0,1,(MAX(BA6,0)/Inputs!$C$6)^Inputs!$C$29) -> 12387.165 | AY7: =Inputs!$C$32*BA6/Inputs!$C$6 -> 6750 | AZ7: =Inputs!$C$33 -> 2000 | BA7: =MAX(BA6+AW7-AX7-AY7-AZ7,0) -> 800000 | BB7: =BB6-AW7 -> 551669.16 | BC7: =Inputs!$C$19*(1-Inputs!$C$71*$H7)+Inputs!$C$21+Inputs!$B$71*$J7 -> 495500 | BD7: =BA7-BC7 -> 304500 | BE7: =IF(BD7<0,1,0) -> 0 | BF7: =MAX(0,MIN(Inputs!$D$36,BK6,BG7+BH7+BI7+Inputs!$D$6-BJ6)) -> 15525.376 | BG7: =Inputs!$D$27*(1+Inputs!$D$28)^($A7/12)*IF(Inputs!$B$71=1,$G7,1)*(1-Inputs!$C$71*$H7*(1-Inputs!$E$54*Inputs!$B$71))*(1+$I7)*IF(Inputs!$D$29=0,1,(MAX(BJ6,0)/Inputs!$D$6)^Inputs!$D$29) -> 9825.3762 | BH7: =Inputs!$D$32*BJ6/Inputs!$D$6 -> 4200 | BI7: =Inputs!$D$33 -> 1500 | BJ7: =MAX(BJ6+BF7-BG7-BH7-BI7,0) -> 880000 | BK7: =BK6-BF7 -> 878862.15 | BL7: =Inputs!$D$19*(1-Inputs!$C$71*$H7)+Inputs!$D$21+Inputs!$B$71*$J7 -> 405300 | BM7: =BJ7-BL7 -> 474700 | BN7: =IF(BM7<0,1,0) -> 0 | BO7: =MAX(0,MIN(Inputs!$B$36,BT6,BP7+BQ7+BR7+Inputs!$B$6-BS6)) -> 22000 | BP7: =Inputs!$B$27*(1+Inputs!$B$28)^($A7/12)*IF(Inputs!$B$72=1,$G7,1)*(1-Inputs!$C$72*$H7*(1-Inputs!$E$54*Inputs!$B$72))*(1+$I7)*IF(Inputs!$B$29=0,1,(MAX(BS6,0)/Inputs!$B$6)^Inputs!$B$29) -> 15097.111 | BQ7: =Inputs!$B$32*BS6/Inputs!$B$6 -> 10699.171 | BR7: =Inputs!$B$33 -> 2500 | BS7: =MAX(BS6+BO7-BP7-BQ7-BR7,0) -> 667355.2 | BT7: =BT6-BO7 -> 327250 | BU7: =Inputs!$B$19*(1-Inputs!$C$72*$H7)+Inputs!$B$21+Inputs!$B$72*$J7 -> 594270.83 | BV7: =BS7-BU7 -> 73084.363 | BW7: =IF(BV7<0,1,0) -> 0 | BX7: =MAX(0,MIN(Inputs!$C$36,CC6,BY7+BZ7+CA7+Inputs!$C$6-CB6)) -> 21229.036 | BY7: =Inputs!$C$27*(1+Inputs!$C$28)^($A7/12)*IF(Inputs!$B$72=1,$G7,1)*(1-Inputs!$C$72*$H7*(1-Inputs!$E$54*Inputs!$B$72))*(1+$I7)*IF(Inputs!$C$29=0,1,(MAX(CB6,0)/Inputs!$C$6)^Inputs!$C$29) -> 12479.036 | BZ7: =Inputs!$C$32*CB6/Inputs!$C$6 -> 6750 | CA7: =Inputs!$C$33 -> 2000 | CB7: =MAX(CB6+BX7-BY7-BZ7-CA7,0) -> 800000 | CC7: =CC6-BX7 -> 551531.41 | CD7: =Inputs!$C$19*(1-Inputs!$C$72*$H7)+Inputs!$C$21+Inputs!$B$72*$J7 -> 494375 | CE7: =CB7-CD7 -> 305625 | CF7: =IF(CE7<0,1,0) -> 0 | CG7: =MAX(0,MIN(Inputs!$D$36,CL6,CH7+CI7+CJ7+Inputs!$D$6-CK6)) -> 15598.247 | CH7: =Inputs!$D$27*(1+Inputs!$D$28)^($A7/12)*IF(Inputs!$B$72=1,$G7,1)*(1-Inputs!$C$72*$H7*(1-Inputs!$E$54*Inputs!$B$72))*(1+$I7)*IF(Inputs!$D$29=0,1,(MAX(CK6,0)/Inputs!$D$6)^Inputs!$D$29) -> 9898.2475 | CI7: =Inputs!$D$32*CK6/Inputs!$D$6 -> 4200 | CJ7: =Inputs!$D$33 -> 1500 | CK7: =MAX(CK6+CG7-CH7-CI7-CJ7,0) -> 880000 | CL7: =CL6-CG7 -> 878752.73 | CM7: =Inputs!$D$19*(1-Inputs!$C$72*$H7)+Inputs!$D$21+Inputs!$B$72*$J7 -> 404272.92 | CN7: =CK7-CM7 -> 475727.08 | CO7: =IF(CN7<0,1,0) -> 0 | CP7: =MAX(0,MIN(Inputs!$B$36,CU6,CQ7+CR7+CS7+Inputs!$B$6-CT6)) -> 22000 | CQ7: =Inputs!$B$27*(1+Inputs!$B$28)^($A7/12)*IF(Inputs!$B$73=1,$G7,1)*(1-Inputs!$C$73*$H7*(1-Inputs!$E$54*Inputs!$B$73))*(1+$I7)*IF(Inputs!$B$29=0,1,(MAX(CT6,0)/Inputs!$B$6)^Inputs!$B$29) -> 14954.745 | CR7: =Inputs!$B$32*CT6/Inputs!$B$6 -> 10700.297 | CS7: =Inputs!$B$33 -> 2500 | CT7: =MAX(CT6+CP7-CQ7-CR7-CS7,0) -> 667567.33 | CU7: =CU6-CP7 -> 327250 | CV7: =Inputs!$B$19*(1-Inputs!$C$73*$H7)+Inputs!$B$21+Inputs!$B$73*$J7 -> 594770.83 | CW7: =CT7-CV7 -> 72796.5 | CX7: =IF(CW7<0,1,0) -> 0 | CY7: =MAX(0,MIN(Inputs!$C$36,DD6,CZ7+DA7+DB7+Inputs!$C$6-DC6)) -> 21111.359 | CZ7: =Inputs!$C$27*(1+Inputs!$C$28)^($A7/12)*IF(Inputs!$B$73=1,$G7,1)*(1-Inputs!$C$73*$H7*(1-Inputs!$E$54*Inputs!$B$73))*(1+$I7)*IF(Inputs!$C$29=0,1,(MAX(DC6,0)/Inputs!$C$6)^Inputs!$C$29) -> 12361.359 | DA7: =Inputs!$C$32*DC6/Inputs!$C$6 -> 6750 | DB7: =Inputs!$C$33 -> 2000 | DC7: =MAX(DC6+CY7-CZ7-DA7-DB7,0) -> 800000 | DD7: =DD6-CY7 -> 551707.93 | DE7: =Inputs!$C$19*(1-Inputs!$C$73*$H7)+Inputs!$C$21+Inputs!$B$73*$J7 -> 494875 | DF7: =DC7-DE7 -> 305125 | DG7: =IF(DF7<0,1,0) -> 0 | DH7: =MAX(0,MIN(Inputs!$D$36,DM6,DI7+DJ7+DK7+Inputs!$D$6-DL6)) -> 15504.907 | DI7: =Inputs!$D$27*(1+Inputs!$D$28)^($A7/12)*IF(Inputs!$B$73=1,$G7,1)*(1-Inputs!$C$73*$H7*(1-Inputs!$E$54*Inputs!$B$73))*(1+$I7)*IF(Inputs!$D$29=0,1,(MAX(DL6,0)/Inputs!$D$6)^Inputs!$D$29) -> 9804.9067 | DJ7: =Inputs!$D$32*DL6/Inputs!$D$6 -> 4200 | DK7: =Inputs!$D$33 -> 1500 | DL7: =MAX(DL6+DH7-DI7-DJ7-DK7,0) -> 880000 | DM7: =DM6-DH7 -> 878892.94 | DN7: =Inputs!$D$19*(1-Inputs!$C$73*$H7)+Inputs!$D$21+Inputs!$B$73*$J7 -> 404772.92 | DO7: =DL7-DN7 -> 475227.08 | DP7: =IF(DO7<0,1,0) -> 0
A8: 3 | B8: =EDATE(Inputs!$B$67,$A8) -> 46357 | C8: =IF(Inputs!$E$47<=0,Inputs!$E$46,Inputs!$E$44+(Inputs!$E$46-Inputs!$E$44)*MIN($A8/Inputs!$E$47,1)) -> 0.2625 | D8: =MIN(Inputs!$E$57,Inputs!$E$55*(1+Inputs!$E$56)^($A8/12))*Inputs!$E$58*(1+Inputs!$E$59)^($A8/12)/Inputs!$E$45 -> 0.45685807 | E8: =MAX(Inputs!$E$44,MIN(C8,D8)) -> 0.2625 | F8: =IF(Inputs!$E$50<=0,Inputs!$E$49,Inputs!$E$48+(Inputs!$E$49-Inputs!$E$48)*MIN($A8/Inputs!$E$50,1)) -> 0.028333333 | G8: =(Inputs!$E$41*(1-E8*Inputs!$E$51)+Inputs!$E$42*(1-F8*Inputs!$E$51))/(Inputs!$E$41*(1-Inputs!$E$44*Inputs!$E$51)+Inputs!$E$42*(1-Inputs!$E$48*Inputs!$E$51)) -> 0.98275296 | H8: =IF(Inputs!$E$53<=0,Inputs!$E$52,Inputs!$E$52*MIN($A8/Inputs!$E$53,1)) -> 0.00625 | I8: =IF(Inputs!$E$64<=0,Inputs!$E$63,Inputs!$E$62+(Inputs!$E$63-Inputs!$E$62)*MIN($A8/Inputs!$E$64,1)) -> 0.00375 | J8: =(E8-Inputs!$E$44)*Inputs!$E$45/Inputs!$E$60*Inputs!$E$61 -> 750 | K8: =IF(D8<C8,1,0) -> 0 | M8: =MAX(0,MIN(Inputs!$B$36,R7,N8+O8+P8+Inputs!$B$6-Q7)) -> 22000 | N8: =Inputs!$B$27*(1+Inputs!$B$28)^($A8/12)*IF(Inputs!$B$70=1,$G8,1)*(1-Inputs!$C$70*$H8*(1-Inputs!$E$54*Inputs!$B$70))*(1+$I8)*IF(Inputs!$B$29=0,1,(MAX(Q7,0)/Inputs!$B$6)^Inputs!$B$29) -> 15241.024 | O8: =Inputs!$B$32*Q7/Inputs!$B$6 -> 10597.676 | P8: =Inputs!$B$33 -> 2500 | Q8: =MAX(Q7+M8-N8-O8-P8,0) -> 660922.41 | R8: =R7-M8 -> 305250 | S8: =Inputs!$B$19*(1-Inputs!$C$70*$H8)+Inputs!$B$21+Inputs!$B$70*$J8 -> 595000 | T8: =Q8-S8 -> 65922.411 | U8: =IF(T8<0,1,0) -> 0 | V8: =MAX(0,MIN(Inputs!$C$36,AA7,W8+X8+Y8+Inputs!$C$6-Z7)) -> 21296.875 | W8: =Inputs!$C$27*(1+Inputs!$C$28)^($A8/12)*IF(Inputs!$B$70=1,$G8,1)*(1-Inputs!$C$70*$H8*(1-Inputs!$E$54*Inputs!$B$70))*(1+$I8)*IF(Inputs!$C$29=0,1,(MAX(Z7,0)/Inputs!$C$6)^Inputs!$C$29) -> 12546.875 | X8: =Inputs!$C$32*Z7/Inputs!$C$6 -> 6750 | Y8: =Inputs!$C$33 -> 2000 | Z8: =MAX(Z7+V8-W8-X8-Y8,0) -> 800000 | AA8: =AA7-V8 -> 530156.25 | AB8: =Inputs!$C$19*(1-Inputs!$C$70*$H8)+Inputs!$C$21+Inputs!$B$70*$J8 -> 495000 | AC8: =Z8-AB8 -> 305000 | AD8: =IF(AC8<0,1,0) -> 0 | AE8: =MAX(0,MIN(Inputs!$D$36,AJ7,AF8+AG8+AH8+Inputs!$D$6-AI7)) -> 15609.608 | AF8: =Inputs!$D$27*(1+Inputs!$D$28)^($A8/12)*IF(Inputs!$B$70=1,$G8,1)*(1-Inputs!$C$70*$H8*(1-Inputs!$E$54*Inputs!$B$70))*(1+$I8)*IF(Inputs!$D$29=0,1,(MAX(AI7,0)/Inputs!$D$6)^Inputs!$D$29) -> 9909.6076 | AG8: =Inputs!$D$32*AI7/Inputs!$D$6 -> 4200 | AH8: =Inputs!$D$33 -> 1500 | AI8: =MAX(AI7+AE8-AF8-AG8-AH8,0) -> 880000 | AJ8: =AJ7-AE8 -> 863080.94 | AK8: =Inputs!$D$19*(1-Inputs!$C$70*$H8)+Inputs!$D$21+Inputs!$B$70*$J8 -> 404800 | AL8: =AI8-AK8 -> 475200 | AM8: =IF(AL8<0,1,0) -> 0 | AN8: =MAX(0,MIN(Inputs!$B$36,AS7,AO8+AP8+AQ8+Inputs!$B$6-AR7)) -> 22000 | AO8: =Inputs!$B$27*(1+Inputs!$B$28)^($A8/12)*IF(Inputs!$B$71=1,$G8,1)*(1-Inputs!$C$71*$H8*(1-Inputs!$E$54*Inputs!$B$71))*(1+$I8)*IF(Inputs!$B$29=0,1,(MAX(AR7,0)/Inputs!$B$6)^Inputs!$B$29) -> 14978.161 | AP8: =Inputs!$B$32*AR7/Inputs!$B$6 -> 10601.8 | AQ8: =Inputs!$B$33 -> 2500 | AR8: =MAX(AR7+AN8-AO8-AP8-AQ8,0) -> 661440.78 | AS8: =AS7-AN8 -> 305250 | AT8: =Inputs!$B$19*(1-Inputs!$C$71*$H8)+Inputs!$B$21+Inputs!$B$71*$J8 -> 595750 | AU8: =AR8-AT8 -> 65690.781 | AV8: =IF(AU8<0,1,0) -> 0 | AW8: =MAX(0,MIN(Inputs!$C$36,BB7,AX8+AY8+AZ8+Inputs!$C$6-BA7)) -> 21080.479 | AX8: =Inputs!$C$27*(1+Inputs!$C$28)^($A8/12)*IF(Inputs!$B$71=1,$G8,1)*(1-Inputs!$C$71*$H8*(1-Inputs!$E$54*Inputs!$B$71))*(1+$I8)*IF(Inputs!$C$29=0,1,(MAX(BA7,0)/Inputs!$C$6)^Inputs!$C$29) -> 12330.479 | AY8: =Inputs!$C$32*BA7/Inputs!$C$6 -> 6750 | AZ8: =Inputs!$C$33 -> 2000 | BA8: =MAX(BA7+AW8-AX8-AY8-AZ8,0) -> 800000 | BB8: =BB7-AW8 -> 530588.68 | BC8: =Inputs!$C$19*(1-Inputs!$C$71*$H8)+Inputs!$C$21+Inputs!$B$71*$J8 -> 495750 | BD8: =BA8-BC8 -> 304250 | BE8: =IF(BD8<0,1,0) -> 0 | BF8: =MAX(0,MIN(Inputs!$D$36,BK7,BG8+BH8+BI8+Inputs!$D$6-BJ7)) -> 15438.696 | BG8: =Inputs!$D$27*(1+Inputs!$D$28)^($A8/12)*IF(Inputs!$B$71=1,$G8,1)*(1-Inputs!$C$71*$H8*(1-Inputs!$E$54*Inputs!$B$71))*(1+$I8)*IF(Inputs!$D$29=0,1,(MAX(BJ7,0)/Inputs!$D$6)^Inputs!$D$29) -> 9738.6962 | BH8: =Inputs!$D$32*BJ7/Inputs!$D$6 -> 4200 | BI8: =Inputs!$D$33 -> 1500 | BJ8: =MAX(BJ7+BF8-BG8-BH8-BI8,0) -> 880000 | BK8: =BK7-BF8 -> 863423.45 | BL8: =Inputs!$D$19*(1-Inputs!$C$71*$H8)+Inputs!$D$21+Inputs!$B$71*$J8 -> 405550 | BM8: =BJ8-BL8 -> 474450 | BN8: =IF(BM8<0,1,0) -> 0 | BO8: =MAX(0,MIN(Inputs!$B$36,BT7,BP8+BQ8+BR8+Inputs!$B$6-BS7)) -> 22000 | BP8: =Inputs!$B$27*(1+Inputs!$B$28)^($A8/12)*IF(Inputs!$B$72=1,$G8,1)*(1-Inputs!$C$72*$H8*(1-Inputs!$E$54*Inputs!$B$72))*(1+$I8)*IF(Inputs!$B$29=0,1,(MAX(BS7,0)/Inputs!$B$6)^Inputs!$B$29) -> 15145.767 | BQ8: =Inputs!$B$32*BS7/Inputs!$B$6 -> 10599.171 | BR8: =Inputs!$B$33 -> 2500 | BS8: =MAX(BS7+BO8-BP8-BQ8-BR8,0) -> 661110.26 | BT8: =BT7-BO8 -> 305250 | BU8: =Inputs!$B$19*(1-Inputs!$C$72*$H8)+Inputs!$B$21+Inputs!$B$72*$J8 -> 593906.25 | BV8: =BS8-BU8 -> 67204.009 | BW8: =IF(BV8<0,1,0) -> 0 | BX8: =MAX(0,MIN(Inputs!$C$36,CC7,BY8+BZ8+CA8+Inputs!$C$6-CB7)) -> 21218.457 | BY8: =Inputs!$C$27*(1+Inputs!$C$28)^($A8/12)*IF(Inputs!$B$72=1,$G8,1)*(1-Inputs!$C$72*$H8*(1-Inputs!$E$54*Inputs!$B$72))*(1+$I8)*IF(Inputs!$C$29=0,1,(MAX(CB7,0)/Inputs!$C$6)^Inputs!$C$29) -> 12468.457 | BZ8: =Inputs!$C$32*CB7/Inputs!$C$6 -> 6750 | CA8: =Inputs!$C$33 -> 2000 | CB8: =MAX(CB7+BX8-BY8-BZ8-CA8,0) -> 800000 | CC8: =CC7-BX8 -> 530312.96 | CD8: =Inputs!$C$19*(1-Inputs!$C$72*$H8)+Inputs!$C$21+Inputs!$B$72*$J8 -> 494062.5 | CE8: =CB8-CD8 -> 305937.5 | CF8: =IF(CE8<0,1,0) -> 0 | CG8: =MAX(0,MIN(Inputs!$D$36,CL7,CH8+CI8+CJ8+Inputs!$D$6-CK7)) -> 15547.673 | CH8: =Inputs!$D$27*(1+Inputs!$D$28)^($A8/12)*IF(Inputs!$B$72=1,$G8,1)*(1-Inputs!$C$72*$H8*(1-Inputs!$E$54*Inputs!$B$72))*(1+$I8)*IF(Inputs!$D$29=0,1,(MAX(CK7,0)/Inputs!$D$6)^Inputs!$D$29) -> 9847.6726 | CI8: =Inputs!$D$32*CK7/Inputs!$D$6 -> 4200 | CJ8: =Inputs!$D$33 -> 1500 | CK8: =MAX(CK7+CG8-CH8-CI8-CJ8,0) -> 880000 | CL8: =CL7-CG8 -> 863205.06 | CM8: =Inputs!$D$19*(1-Inputs!$C$72*$H8)+Inputs!$D$21+Inputs!$B$72*$J8 -> 404009.38 | CN8: =CK8-CM8 -> 475990.62 | CO8: =IF(CN8<0,1,0) -> 0 | CP8: =MAX(0,MIN(Inputs!$B$36,CU7,CQ8+CR8+CS8+Inputs!$B$6-CT7)) -> 22000 | CQ8: =Inputs!$B$27*(1+Inputs!$B$28)^($A8/12)*IF(Inputs!$B$73=1,$G8,1)*(1-Inputs!$C$73*$H8*(1-Inputs!$E$54*Inputs!$B$73))*(1+$I8)*IF(Inputs!$B$29=0,1,(MAX(CT7,0)/Inputs!$B$6)^Inputs!$B$29) -> 14931.354 | CR8: =Inputs!$B$32*CT7/Inputs!$B$6 -> 10602.54 | CS8: =Inputs!$B$33 -> 2500 | CT8: =MAX(CT7+CP8-CQ8-CR8-CS8,0) -> 661533.44 | CU8: =CU7-CP8 -> 305250 | CV8: =Inputs!$B$19*(1-Inputs!$C$73*$H8)+Inputs!$B$21+Inputs!$B$73*$J8 -> 594656.25 | CW8: =CT8-CV8 -> 66877.189 | CX8: =IF(CW8<0,1,0) -> 0 | CY8: =MAX(0,MIN(Inputs!$C$36,DD7,CZ8+DA8+DB8+Inputs!$C$6-DC7)) -> 21041.946 | CZ8: =Inputs!$C$27*(1+Inputs!$C$28)^($A8/12)*IF(Inputs!$B$73=1,$G8,1)*(1-Inputs!$C$73*$H8*(1-Inputs!$E$54*Inputs!$B$73))*(1+$I8)*IF(Inputs!$C$29=0,1,(MAX(DC7,0)/Inputs!$C$6)^Inputs!$C$29) -> 12291.946 | DA8: =Inputs!$C$32*DC7/Inputs!$C$6 -> 6750 | DB8: =Inputs!$C$33 -> 2000 | DC8: =MAX(DC7+CY8-CZ8-DA8-DB8,0) -> 800000 | DD8: =DD7-CY8 -> 530665.99 | DE8: =Inputs!$C$19*(1-Inputs!$C$73*$H8)+Inputs!$C$21+Inputs!$B$73*$J8 -> 494812.5 | DF8: =DC8-DE8 -> 305187.5 | DG8: =IF(DF8<0,1,0) -> 0 | DH8: =MAX(0,MIN(Inputs!$D$36,DM7,DI8+DJ8+DK8+Inputs!$D$6-DL7)) -> 15408.263 | DI8: =Inputs!$D$27*(1+Inputs!$D$28)^($A8/12)*IF(Inputs!$B$73=1,$G8,1)*(1-Inputs!$C$73*$H8*(1-Inputs!$E$54*Inputs!$B$73))*(1+$I8)*IF(Inputs!$D$29=0,1,(MAX(DL7,0)/Inputs!$D$6)^Inputs!$D$29) -> 9708.2628 | DJ8: =Inputs!$D$32*DL7/Inputs!$D$6 -> 4200 | DK8: =Inputs!$D$33 -> 1500 | DL8: =MAX(DL7+DH8-DI8-DJ8-DK8,0) -> 880000 | DM8: =DM7-DH8 -> 863484.68 | DN8: =Inputs!$D$19*(1-Inputs!$C$73*$H8)+Inputs!$D$21+Inputs!$B$73*$J8 -> 404759.38 | DO8: =DL8-DN8 -> 475240.62 | DP8: =IF(DO8<0,1,0) -> 0
